<?xml version="1.0" ?>
<sdf version="1.7">
  <world name="default">
    <scene>
      <ambient>0.4 0.4 0.4 1.0</ambient>
      <background>0.7 0.7 0.7 1.0</background>
      <sky>
        <clouds/>
      </sky>
    </scene>

    <light name="sun" type="directional">
      <cast_shadows>true</cast_shadows>
      <pose>0 0 10 0 -0 0</pose>
      <diffuse>1 1 1 1</diffuse>
      <specular>1 1 1 1</specular>
      <attenuation>
        <range>1000</range>
        <constant>0.9</constant>
        <linear>0.01</linear>
        <quadratic>0.001</quadratic>
      </attenuation>
      <direction>0.1 0.1 -0.9</direction>
    </light>

    <model name="grass_field">
      <pose>49.4 1.25 0 0 0 0</pose>
      <static>true</static>
      <link name="link">
        <collision name="collision">
          <geometry>
            <plane>
              <normal>0 0 1</normal>
              <size>100 100</size>
            </plane>
          </geometry>
          <surface>
            <contact>
              <collide_bitmask>65535</collide_bitmask>
              <ode/>
            </contact>
            <friction>
              <ode>
                <mu>100</mu>
                <mu2>50</mu2>
              </ode>
              <torsional>
                <ode/>
              </torsional>
            </friction>
          </surface>
            <max_contacts>10</max_contacts>
        </collision>
        <visual name="visual">
          <cast_shadows>0</cast_shadows>
          <geometry>
            <plane>
              <normal>0 0 1</normal>
              <size>100 100</size>
            </plane>
          </geometry>
          <material>
            <script>
              <uri>file://media/materials/scripts/gazebo.material</uri>
              <name>Gazebo/Green</name>
            </script>
          </material>
        </visual>
        <self_collide>0</self_collide>
        <enable_wind>0</enable_wind>
        <kinematic>0</kinematic>
      </link>
    </model>
   
    <gravity>0 0 -9.8</gravity>
    <magnetic_field>6e-06 2.3e-05 -4.2e-05</magnetic_field>
    <atmosphere type='adiabatic'/>
    <physics type='ode'>
      <max_step_size>0.001</max_step_size>
      <real_time_factor>1</real_time_factor>
      <real_time_update_rate>1000</real_time_update_rate>
    </physics>
    <scene>
      <ambient>0.4 0.4 0.4 1</ambient>
      <background>0.7 0.7 0.7 1</background>
      <shadows>1</shadows>
    </scene>
    <wind/>
    <spherical_coordinates>
      <surface_model>EARTH_WGS84</surface_model>
      <latitude_deg>0</latitude_deg>
      <longitude_deg>0</longitude_deg>
      <elevation>0</elevation>
      <heading_deg>0</heading_deg>
    </spherical_coordinates>
    <state world_name='default'>
      <sim_time>1001 182000000</sim_time>
      <real_time>53 369119915</real_time>
      <wall_time>1629458598 820844655</wall_time>
      <iterations>35470</iterations>

      <light name="sun" type="directional">
        <pose>0 0 10 0 -0 0</pose>
      </light>

      <model name="grass_field">
        <pose>49.4 1.25 0 0 0 0</pose>
        <scale>1 1 1</scale>
        <link name="link">
          <pose>49.4 1.25 0 0 0 0</pose>
          <velocity> 0 0 0 0 0 0</velocity>
          <acceleration> 0 0 0 0 0 0</acceleration>
          <wrench> 0 0 0 0 0 0</wrench>
        </link>
      </model>

      <model name="orange_board_1">
        <pose>0.4 50.25 0 0 0 0</pose>
        <scale>1 1 1</scale>
        <link name="link">
          <pose>0.4 50.25 0 0 0 0</pose>
          <velocity> 0 0 0 0 0 0</velocity>
          <acceleration> 0 0 0 0 0 0</acceleration>
          <wrench> 0 0 0 0 0 0</wrench>
        </link>
      </model>

      <model name="orange_board_2">
        <pose>98.4 50.25 0 0 0 0</pose>
        <scale>1 1 1</scale>
        <link name="link">
          <pose>98.4 50.25 0 0 0 0</pose>
          <velocity> 0 0 0 0 0 0</velocity>
          <acceleration> 0 0 0 0 0 0</acceleration>
          <wrench> 0 0 0 0 0 0</wrench>
        </link>
      </model>

      <model name="orange_board_3">
        <pose>98.4 -47.75 0 0 0 0</pose>
        <scale>1 1 1</scale>
        <link name="link">
          <pose>98.4 -47.75 0 0 0 0</pose>
          <velocity> 0 0 0 0 0 0</velocity>
          <acceleration> 0 0 0 0 0 0</acceleration>
          <wrench> 0 0 0 0 0 0</wrench>
        </link>
      </model>

      <model name="orange_board_4">
        <pose>0.4 -47.75 0 0 0 0</pose>
        <link name="link">
          <pose>0.4 -47.75 0 0 0 0</pose>
          <velocity> 0 0 0 0 0 0</velocity>
          <acceleration> 0 0 0 0 0 0</acceleration>
          <wrench> 0 0 0 0 0 0</wrench>
        </link>
      </model>
      
      <model name="wall1">
        <pose>3.125 1.25 0.75 0 0 0</pose>
        <link name="link">
          <pose>3.125 1.25 0.75 0 0 0</pose>
          <velocity> 0 0 0 0 0 0</velocity>
          <acceleration> 0 0 0 0 0 0</acceleration>
          <wrench> 0 0 0 0 0 0</wrench>
        </link>
      </model>

      <model name="wall2">
        <pose>6.875 1.25 0.75 0 0 1.5708</pose>
        <link name="link">
          <pose>6.875 1.25 0.75 0 0 1.5708</pose>
          <velocity> 0 0 0 0 0 0</velocity>
          <acceleration> 0 0 0 0 0 0</acceleration>
          <wrench> 0 0 0 0 0 0</wrench>
        </link>
      </model>

      <model name="wall3">
        <pose>1.85 -1.285 0.75 0 0 0</pose>
        <link name="link">
          <pose>1.85 -1.285 0.75 0 0 0</pose>
          <velocity> 0 0 0 0 0 0</velocity>
          <acceleration> 0 0 0 0 0 0</acceleration>
          <wrench> 0 0 0 0 0 0</wrench>
        </link>
      </model>

      <model name="wall4">
        <pose>4.325 -2.5 0.75 0 0 1.5708</pose>
        <link name="link">
          <pose>4.325 -2.5 0.75 0 0 1.5708</pose>
          <velocity> 0 0 0 0 0 0</velocity>
          <acceleration> 0 0 0 0 0 0</acceleration>
          <wrench> 0 0 0 0 0 0</wrench>
        </link>
      </model>

      <model name="wall5">
        <pose>1.85 3.785 0.75 0 0 0</pose>
        <link name="link">
          <pose>1.85 3.785 0.75 0 0 0</pose>
          <velocity> 0 0 0 0 0 0</velocity>
          <acceleration> 0 0 0 0 0 0</acceleration>
          <wrench> 0 0 0 0 0 0</wrench>
        </link>
      </model>

      <model name="wall6">
        <pose>4.325 5 0.75 0 0 1.5708</pose>
        <link name="link">
          <pose>4.325 5 0.75 0 0 1.5708</pose>
          <velocity> 0 0 0 0 0 0</velocity>
          <acceleration> 0 0 0 0 0 0</acceleration>
          <wrench> 0 0 0 0 0 0</wrench>
        </link>
      </model>

      <model name="right_start_indoor">
        <pose>0 0 0.025 0 0 0</pose>
        <link name="link">
          <pose>0 0 0.025 0 0 0</pose>
          <velocity> 0 0 0 0 0 0</velocity>
          <acceleration> 0 0 0 0 0 0</acceleration>
          <wrench> 0 0 0 0 0 0</wrench>
        </link>
      </model>
      
      <model name="left_start_indoor">
        <pose>0 2.5 0.025 0 0 0</pose>
        <link name="link">
          <pose>0 2.5 0.025 0 0 0</pose>
          <velocity> 0 0 0 0 0 0</velocity>
          <acceleration> 0 0 0 0 0 0</acceleration>
          <wrench> 0 0 0 0 0 0</wrench>
        </link>
      </model>

      <model name="right_start_outdoor">
        <pose>0 -3.15 0.025 0 0 0</pose>
        <link name="link">
          <pose>0 -3.15 0.025 0 0 0</pose>
          <velocity> 0 0 0 0 0 0</velocity>
          <acceleration> 0 0 0 0 0 0</acceleration>
          <wrench> 0 0 0 0 0 0</wrench>
        </link>
      </model>

      <model name="left_start_outdoor">
        <pose>0 5.65 0.025 0 0 0</pose>
        <link name="link">
          <pose>0 5.65 0.025 0 0 0</pose>
          <velocity> 0 0 0 0 0 0</velocity>
          <acceleration> 0 0 0 0 0 0</acceleration>
          <wrench> 0 0 0 0 0 0</wrench>
        </link>
      </model>

      <model name="right_dropzone_area">
        <pose>5.6 -5 0.026 0 0 0</pose>
        <link name="link">
        <pose>5.6 -5 0.026 0 0 0</pose>
        <velocity> 0 0 0 0 0 0</velocity>
          <acceleration> 0 0 0 0 0 0</acceleration>
          <wrench> 0 0 0 0 0 0</wrench>
        </link>
      </model>
      
      <model name="right_dropzone_area_barrier">
        <pose>5.6 -5 0.025 0 0 0</pose>
        <link name="link">
          <pose>5.6 -5 0.025 0 0 0</pose>
          <velocity> 0 0 0 0 0 0</velocity>
          <acceleration> 0 0 0 0 0 0</acceleration>
          <wrench> 0 0 0 0 0 0</wrench>
        </link>
      </model>

      <model name="left_dropzone_area">
        <pose>5.6 7.5 0.026 0 0 0</pose>
        <link name="link">
        <pose>5.6 7.5 0.026 0 0 0</pose>
        <velocity> 0 0 0 0 0 0</velocity>
          <acceleration> 0 0 0 0 0 0</acceleration>
          <wrench> 0 0 0 0 0 0</wrench>
        </link>
      </model>
      
      <model name="left_dropzone_area_barrier">
        <pose>5.6 7.5 0.025 0 0 0</pose>
        <link name="link">
          <pose>5.6 7.5 0.025 0 0 0</pose>
          <velocity> 0 0 0 0 0 0</velocity>
          <acceleration> 0 0 0 0 0 0</acceleration>
          <wrench> 0 0 0 0 0 0</wrench>
        </link>
      </model>

      <model name='iris_demo'>
        <pose>-1e-06 0 0.049856 0.000927 -1.5e-05 -1.5708</pose>
        <scale>1 1 1</scale>
        <link name='gimbal_small_2d::base_link'>
          <pose>-0.010066 1e-06 0.119846 1.56999 -0.000927 -0.000796</pose>
          <velocity>-1.3e-05 5.1e-05 -3e-06 -0.000109 -6e-05 7.8e-05</velocity>
          <acceleration>-0.000695 0.006401 -0.001479 -0.105178 -0.012481 -0.032565</acceleration>
          <wrench>-0.000139 0.00128 -0.000296 0 -0 0</wrench>
        </link>
        <link name='gimbal_small_2d::tilt_link'>
          <pose>-0.010101 -0.019982 0.139863 3.14076 -0.000926 -0.000796</pose>
          <velocity>-1.4e-05 5.8e-05 -1e-06 5.8e-05 -2.8e-05 7.8e-05</velocity>
          <acceleration>-0.001516 0.018547 0.000622 -0.613206 -0.014594 -0.033112</acceleration>
          <wrench>-0.000106 0.001298 4.4e-05 0 -0 0</wrench>
        </link>
        <link name='iris::base_link'>
          <pose>-0.000182 3e-06 0.244779 -1.5e-05 -0.000927 4e-06</pose>
          <velocity>-1.7e-05 5e-05 -2e-06 -0.000257 -8.6e-05 0</velocity>
          <acceleration>-0.002421 0.01953 -0.001356 -0.100138 -0.012409 -8.4e-05</acceleration>
          <wrench>-0.003632 0.029295 -0.002035 0 -0 0</wrench>
        </link>
        <link name='iris::iris/ground_truth/odometry_sensorgt_link'>
          <pose>-0.000182 3e-06 0.244779 -1.5e-05 -0.000927 4e-06</pose>
          <velocity>-2e-05 6.1e-05 -2e-06 -7.4e-05 -5.1e-05 0.000114</velocity>
          <acceleration>-0.002353 0.019556 -0.001358 -0.106997 -0.013261 -0.04047</acceleration>
          <wrench>-0.000353 0.002933 -0.000204 0 -0 0</wrench>
        </link>
        <link name='iris::iris/imu_link'>
          <pose>-0.000182 3e-06 0.244779 -1.5e-05 -0.000927 4e-06</pose>
          <velocity>-1.9e-05 6e-05 -2e-06 -7.4e-05 -5.1e-05 0.000114</velocity>
          <acceleration>-0.002356 0.019541 -0.001358 -0.106974 -0.013258 -0.040477</acceleration>
          <wrench>-0.000353 0.002931 -0.000204 0 -0 0</wrench>
        </link>
        <link name='iris::rotor_0'>
          <pose>0.129797 -0.219996 0.267902 -0.000741 0.000557 2.19862</pose>
          <velocity>-1e-05 6.8e-05 2.1e-05 -6.8e-05 -8e-05 -3.6e-05</velocity>
          <acceleration>-0.004608 0.020848 0.023862 0.161664 -0.257481 0.001071</acceleration>
          <wrench>-0.000115 0.000521 0.000597 0 -0 0</wrench>
        </link>
        <link name='iris::rotor_1'>
          <pose>-0.130204 0.200003 0.267655 0.000209 0.000903 -2.93043</pose>
          <velocity>-3e-05 5.5e-05 -2.3e-05 -7.3e-05 -4.9e-05 -3.5e-05</velocity>
          <acceleration>-0.000895 0.023106 -0.024365 -0.143135 -0.041903 0.000768</acceleration>
          <wrench>-2.2e-05 0.000578 -0.000609 0 -0 0</wrench>
        </link>
        <link name='iris::rotor_2'>
          <pose>0.129796 0.220004 0.267896 0.00056 0.000738 -2.50848</pose>
          <velocity>-3.1e-05 6.8e-05 -1.1e-05 -6.6e-05 -3.5e-05 -3.6e-05</velocity>
          <acceleration>-0.000714 0.020824 -0.023014 -0.121636 -0.091578 0.000806</acceleration>
          <wrench>-1.8e-05 0.000521 -0.000575 0 -0 0</wrench>
        </link>
        <link name='iris::rotor_3'>
          <pose>-0.130202 -0.199997 0.267661 0.000551 0.000745 -2.52072</pose>
          <velocity>-1.1e-05 5.5e-05 5e-06 -6.4e-05 -3.6e-05 -3.6e-05</velocity>
          <acceleration>-0.004432 0.02309 0.018108 -0.126082 -0.093123 0.000777</acceleration>
          <wrench>-0.000111 0.000577 0.000453 0 -0 0</wrench>
        </link>
        <link name='realsense_biasa::base_link'>
          <pose>0.104813 3e-06 0.249953 -1.5e-05 -0.000927 4e-06</pose>
          <velocity>-1.9e-05 6.4e-05 4e-06 -8.4e-05 -5.2e-05 0.000105</velocity>
          <acceleration>-0.002441 0.019148 1.6e-05 -0.105017 -0.013051 -0.037903</acceleration>
          <wrench>-0.00015 0.001179 1e-06 0 -0 0</wrench>
        </link>
      </model>
    </state>
    

    <gui fullscreen='0'>
      <camera name='user_camera'>
        <pose>-5.87086 0.111934 3.46065 0 0.437793 0.049083673</pose>
        <view_controller>orbit</view_controller>
        <projection_type>perspective</projection_type>
      </camera>
    </gui>

    <model name="orange_board_1">
      <pose>0.4 50.25 0 0 0 0</pose>
      <static>true</static>
      <link name="link">
        <collision name="collision">
          <geometry>
            <box>
              <size>2 2 0.001</size>
            </box>
          </geometry>
        </collision>
        <visual name="visual">
          <geometry>
            <box>
              <size>2 2 0.001</size>
            </box>
          </geometry>
          <material>
            <script>
              <uri>file://media/materials/scripts/gazebo.material</uri>
              <name>Gazebo/Orange</name>
            </script>
          </material>
        </visual>
      </link>
    </model>

    <model name="orange_board_2">
      <pose>98.4 50.25 0 0 0 0</pose>
      <static>true</static>
      <link name="link">
        <collision name="collision">
          <geometry>
            <box>
              <size>2 2 0.001</size>
            </box>
          </geometry>
        </collision>
        <visual name="visual">
          <geometry>
            <box>
              <size>2 2 0.001</size>
            </box>
          </geometry>
          <material>
            <script>
              <uri>file://media/materials/scripts/gazebo.material</uri>
              <name>Gazebo/Orange</name>
            </script>
          </material>
        </visual>
      </link>
    </model>
    
    <model name="orange_board_3">
      <pose>98.4 -47.75 0 0 0 0</pose>
      <static>true</static>
      <link name="link">
        <collision name="collision">
          <geometry>
            <box>
              <size>2 2 0.001</size>
            </box>
          </geometry>
        </collision>
        <visual name="visual">
          <geometry>
            <box>
              <size>2 2 0.001</size>
            </box>
          </geometry>
          <material>
            <script>
              <uri>file://media/materials/scripts/gazebo.material</uri>
              <name>Gazebo/Orange</name>
            </script>
          </material>
        </visual>
      </link>
    </model>
    
    <model name="orange_board_4">
      <pose>0.4 -47.75 0 0 0 0</pose>
      <static>true</static>
      <link name="link">
        <collision name="collision">
          <geometry>
            <box>
              <size>2 2 0.001</size>
            </box>
          </geometry>
        </collision>
        <visual name="visual">
          <geometry>
            <box>
              <size>2 2 0.001</size>
            </box>
          </geometry>
          <material>
            <script>
              <uri>file://media/materials/scripts/gazebo.material</uri>
              <name>Gazebo/Orange</name>
            </script>
          </material>
        </visual>
      </link>
    </model>
    
    <model name="wall1">
      <pose>3.125 1.25 0.75 0 0 0</pose>
      <static>true</static>
      <link name="link">
        <collision name="collision">
          <geometry>
            <box>
              <size>7.45 0.04 1.5</size>
            </box>
          </geometry>
        </collision>
        <visual name="visual">
          <geometry>
            <box>
              <size>7.45 0.04 1.5</size>
            </box>
          </geometry>
          <material>
            <ambient>0.5 0.5 0.5 1</ambient>
            <diffuse>0.5 0.5 0.5 1</diffuse>
            <specular>0.1 0.1 0.1 1</specular>
            <emissive>0 0 0 0</emissive>
          </material>
        </visual>
      </link>
    </model>    
    
    <model name="wall2">
      <pose>6.875 1.25 0.75 0 0 1.5708</pose>
      <static>true</static>
      <link name="link">
        <collision name="collision">
          <geometry>
            <box>
              <size>10 0.05 1.5</size>
            </box>
          </geometry>
        </collision>
        <visual name="visual">
          <geometry>
            <box>
              <size>10 0.05 1.5</size>
            </box>
          </geometry>
          <material>
            <ambient>0.5 0.5 0.5 1</ambient>
            <diffuse>0.5 0.5 0.5 1</diffuse>
            <specular>0.1 0.1 0.1 1</specular>
            <emissive>0 0 0 0</emissive>
          </material>
        </visual>
      </link>
    </model>    
    
    <model name="wall3">
      <pose>1.85 -1.285 0.75 0 0 0</pose>
      <static>true</static>
      <link name="link">
        <collision name="collision">
          <geometry>
            <box>
              <size>4.9 0.07 1.5</size>
            </box>
          </geometry>
        </collision>
        <visual name="visual">
          <geometry>
            <box>
              <size>4.9 0.07 1.5</size>
            </box>
          </geometry>
          <material>
            <ambient>0.5 0.5 0.5 1</ambient>
            <diffuse>0.5 0.5 0.5 1</diffuse>
            <specular>0.1 0.1 0.1 1</specular>
            <emissive>0 0 0 0</emissive>
          </material>
        </visual>
      </link>
    </model> 
    
    <model name="wall4">
      <pose>4.325 -2.5 0.75 0 0 1.5708</pose>
      <static>true</static>
      <link name="link">
        <collision name="collision">
          <geometry>
            <box>
              <size>2.5 0.05 1.5</size>
            </box>
          </geometry>
        </collision>
        <visual name="visual">
          <geometry>
            <box>
              <size>2.5 0.05 1.5</size>
            </box>
          </geometry>
          <material>
            <ambient>0.5 0.5 0.5 1</ambient>
            <diffuse>0.5 0.5 0.5 1</diffuse>
            <specular>0.1 0.1 0.1 1</specular>
            <emissive>0 0 0 0</emissive>
          </material>
        </visual>
      </link>
    </model>
    
    <model name="wall5">
      <pose>1.85 3.785 0.75 0 0 0</pose>
      <static>true</static>
      <link name="link">
        <collision name="collision">
          <geometry>
            <box>
              <size>4.9 0.07 1.5</size>
            </box>
          </geometry>
        </collision>
        <visual name="visual">
          <geometry>
            <box>
              <size>4.9 0.07 1.5</size>
            </box>
          </geometry>
          <material>
            <ambient>0.5 0.5 0.5 1</ambient>
            <diffuse>0.5 0.5 0.5 1</diffuse>
            <specular>0.1 0.1 0.1 1</specular>
            <emissive>0 0 0 0</emissive>
          </material>
        </visual>
      </link>
    </model>
    
    <model name="wall6">
      <pose>4.325 5 0.75 0 0 1.5708</pose>
      <static>true</static>
      <link name="link">
        <collision name="collision">
          <geometry>
            <box>
              <size>2.5 0.05 1.5</size>
            </box>
          </geometry>
        </collision>
        <visual name="visual">
          <geometry>
            <box>
              <size>2.5 0.05 1.5</size>
            </box>
          </geometry>
          <material>
            <ambient>0.5 0.5 0.5 1</ambient>
            <diffuse>0.5 0.5 0.5 1</diffuse>
            <specular>0.1 0.1 0.1 1</specular>
            <emissive>0 0 0 0</emissive>
          </material>
        </visual>
      </link>
    </model>
    
    <model name="right_start_indoor">
      <pose>0 0 0.025 0 0 0</pose>
      <static>true</static>
      <link name="link">
        <collision name="collision">
          <geometry>
            <box>
              <size>1.2 1.2 0.05</size>
            </box>
          </geometry>
        </collision>
        <visual name="visual">
          <geometry>
            <box>
              <size>1.2 1.2 0.05</size>
            </box>
          </geometry>
          <material>
            <ambient>0.5 0.5 0.5 1</ambient>
            <diffuse>0.5 0.5 0.5 1</diffuse>
            <specular>0.1 0.1 0.1 1</specular>
            <emissive>0 0 0 0</emissive>
          </material>
        </visual>
      </link>
    </model>
    
    <model name="left_start_indoor">
      <pose>0 2.5 0.025 0 0 0</pose>
      <static>true</static>
      <link name="link">
        <collision name="collision">
          <geometry>
            <box>
              <size>1.2 1.2 0.05</size>
            </box>
          </geometry>
        </collision>
        <visual name="visual">
          <geometry>
            <box>
              <size>1.2 1.2 0.05</size>
            </box>
          </geometry>
          <material>
            <ambient>0.5 0.5 0.5 1</ambient>
            <diffuse>0.5 0.5 0.5 1</diffuse>
            <specular>0.1 0.1 0.1 1</specular>
            <emissive>0 0 0 0</emissive>
          </material>
        </visual>
      </link>
    </model>
    
    <model name="right_start_outdoor">
      <pose>0 -3.15 0.025 0 0 0</pose>
      <static>true</static>
      <link name="link">
        <collision name="collision">
          <geometry>
            <box>
              <size>1.2 1.2 0.05</size>
            </box>
          </geometry>
        </collision>
        <visual name="visual">
          <geometry>
            <box>
              <size>1.2 1.2 0.05</size>
            </box>
          </geometry>
          <material>
            <ambient>0.5 0.5 0.5 1</ambient>
            <diffuse>0.5 0.5 0.5 1</diffuse>
            <specular>0.1 0.1 0.1 1</specular>
            <emissive>0 0 0 0</emissive>
          </material>
        </visual>
      </link>
    </model>
    
    <model name="left_start_outdoor">
      <pose>0 5.65 0.025 0 0 0</pose>
      <static>true</static>
      <link name="link">
        <collision name="collision">
          <geometry>
            <box>
              <size>1.2 1.2 0.05</size>
            </box>
          </geometry>
        </collision>
        <visual name="visual">
          <geometry>
            <box>
              <size>1.2 1.2 0.05</size>
            </box>
          </geometry>
          <material>
            <ambient>0.5 0.5 0.5 1</ambient>
            <diffuse>0.5 0.5 0.5 1</diffuse>
            <specular>0.1 0.1 0.1 1</specular>
            <emissive>0 0 0 0</emissive>
          </material>
        </visual>
      </link>
    </model>

    <model name="right_dropzone_area">
      <pose>5.6 -5 0.026 0 0 0</pose>
      <static>true</static>
      <link name="link">
        <collision name="collision">
          <geometry>
            <box>
              <size>2.3 2.3 0.001</size>
            </box>
          </geometry>
        </collision>
        <visual name="visual">
          <geometry>
            <box>
              <size>2.3 2.3 0.001</size>
            </box>
          </geometry>
          <material>
            <script>
              <uri>file://media/materials/scripts/gazebo.material</uri>
              <name>Gazebo/Green</name>
            </script>
          </material>
        </visual>
      </link>
    </model>

    <model name="right_dropzone_area_barrier">
      <pose>5.6 -5 0.025 0 0 0</pose>
      <static>true</static>
      <link name="link">
        <collision name="collision">
          <geometry>
            <box>
              <size>2.5 2.5 0.001</size>
            </box>
          </geometry>
        </collision>
        <visual name="visual">
          <geometry>
            <box>
              <size>2.5 2.5 0.001</size>
            </box>
          </geometry>
          <material>
            <script>
              <uri>file://media/materials/scripts/gazebo.material</uri>
              <name>Gazebo/White</name>
            </script>
          </material>
        </visual>
      </link>
    </model>

    <model name="left_dropzone_area">
      <pose>5.6 7.5 0.026 0 0 0</pose>
      <static>true</static>
      <link name="link">
        <collision name="collision">
          <geometry>
            <box>
              <size>2.3 2.3 0.001</size>
            </box>
          </geometry>
        </collision>
        <visual name="visual">
          <geometry>
            <box>
              <size>2.3 2.3 0.001</size>
            </box>
          </geometry>
          <material>
            <script>
              <uri>file://media/materials/scripts/gazebo.material</uri>
              <name>Gazebo/Green</name>
            </script>
          </material>
        </visual>
      </link>
    </model>

    <model name="left_dropzone_area_barrier">
      <pose>5.6 7.5 0.025 0 0 0</pose>
      <static>true</static>
      <link name="link">
        <collision name="collision">
          <geometry>
            <box>
              <size>2.5 2.5 0.001</size>
            </box>
          </geometry>
        </collision>
        <visual name="visual">
          <geometry>
            <box>
              <size>2.5 2.5 0.001</size>
            </box>
          </geometry>
          <material>
            <script>
              <uri>file://media/materials/scripts/gazebo.material</uri>
              <name>Gazebo/White</name>
            </script>
          </material>
        </visual>
      </link>
    </model>

    <model name='iris_demo'>
      <frame name='iris::__model__' attached_to='iris::base_link'>
        <pose relative_to='__model__'>0 0 0.194923 0 -0 1.5708</pose>
      </frame>
      <link name='iris::base_link'>
        <velocity_decay>
          <linear>0</linear>
          <angular>0</angular>
        </velocity_decay>
        <inertial>
          <pose>0 0 0 0 -0 0</pose>
          <mass>1.5</mass>
          <inertia>
            <ixx>0.008</ixx>
            <ixy>0</ixy>
            <ixz>0</ixz>
            <iyy>0.015</iyy>
            <iyz>0</iyz>
            <izz>0.017</izz>
          </inertia>
        </inertial>
        <collision name='base_link_collision'>
          <pose>0 0 -0.08 0 -0 0</pose>
          <geometry>
            <box>
              <size>0.47 0.47 0.23</size>
            </box>
          </geometry>
          <surface>
            <contact>
              <ode>
                <max_vel>100</max_vel>
                <min_depth>0.001</min_depth>
              </ode>
            </contact>
            <friction>
              <ode>
                <mu>1</mu>
                <mu2>1</mu2>
              </ode>
              <torsional>
                <ode/>
              </torsional>
            </friction>
            <bounce/>
          </surface>
          <max_contacts>10</max_contacts>
        </collision>
        <visual name='base_link_visual'>
          <geometry>
            <mesh>
              <uri>model://iris_with_standoffs/meshes/iris.dae</uri>
            </mesh>
          </geometry>
          <material>
            <script>
              <name>Gazebo/DarkGrey</name>
              <uri>__default__</uri>
            </script>
          </material>
        </visual>
        <visual name='front_left_leg_visual'>
          <pose>0.123 0.22 -0.11 0 -0 0</pose>
          <geometry>
            <cylinder>
              <radius>0.005</radius>
              <length>0.17</length>
            </cylinder>
          </geometry>
          <material>
            <script>
              <name>Gazebo/FlatBlack</name>
              <uri>file://media/materials/scripts/gazebo.material</uri>
            </script>
          </material>
        </visual>
        <visual name='front_right_leg_visual'>
          <pose>0.123 -0.22 -0.11 0 -0 0</pose>
          <geometry>
            <cylinder>
              <radius>0.005</radius>
              <length>0.17</length>
            </cylinder>
          </geometry>
          <material>
            <script>
              <name>Gazebo/FlatBlack</name>
              <uri>file://media/materials/scripts/gazebo.material</uri>
            </script>
          </material>
        </visual>
        <visual name='rear_left_leg_visual'>
          <pose>-0.14 0.21 -0.11 0 -0 0</pose>
          <geometry>
            <cylinder>
              <radius>0.005</radius>
              <length>0.17</length>
            </cylinder>
          </geometry>
          <material>
            <script>
              <name>Gazebo/FlatBlack</name>
              <uri>file://media/materials/scripts/gazebo.material</uri>
            </script>
          </material>
        </visual>
        <visual name='rear_right_leg_visual'>
          <pose>-0.14 -0.21 -0.11 0 -0 0</pose>
          <geometry>
            <cylinder>
              <radius>0.005</radius>
              <length>0.17</length>
            </cylinder>
          </geometry>
          <material>
            <script>
              <name>Gazebo/FlatBlack</name>
              <uri>file://media/materials/scripts/gazebo.material</uri>
            </script>
          </material>
        </visual>
        <pose relative_to='iris::__model__'>0 0 0 0 -0 0</pose>
        <self_collide>0</self_collide>
        <enable_wind>0</enable_wind>
        <kinematic>0</kinematic>
      </link>
      <link name='iris::iris/ground_truth/odometry_sensorgt_link'>
        <pose relative_to='iris::__model__'>0 0 0 0 -0 0</pose>
        <inertial>
          <pose>0 0 0 0 -0 0</pose>
          <mass>0.15</mass>
          <inertia>
            <ixx>0.0001</ixx>
            <ixy>0</ixy>
            <ixz>0</ixz>
            <iyy>0.0002</iyy>
            <iyz>0</iyz>
            <izz>0.0002</izz>
          </inertia>
        </inertial>
        <self_collide>0</self_collide>
        <enable_wind>0</enable_wind>
        <kinematic>0</kinematic>
      </link>
      <joint name='iris::iris/ground_truth/odometry_sensorgt_joint' type='revolute'>
        <child>iris::iris/ground_truth/odometry_sensorgt_link</child>
        <parent>iris::base_link</parent>
        <axis>
          <xyz expressed_in='iris::__model__'>0 0 1</xyz>
          <limit>
            <lower>0</lower>
            <upper>0</upper>
            <effort>0</effort>
            <velocity>0</velocity>
          </limit>
          <dynamics>
            <damping>1</damping>
            <spring_reference>0</spring_reference>
            <spring_stiffness>0</spring_stiffness>
          </dynamics>
        </axis>
        <physics>
          <ode>
            <implicit_spring_damper>1</implicit_spring_damper>
            <limit>
              <cfm>0</cfm>
              <erp>0.2</erp>
            </limit>
          </ode>
        </physics>
      </joint>
      <link name='iris::iris/imu_link'>
        <inertial>
          <pose>0 0 0 0 -0 0</pose>
          <mass>0.15</mass>
          <inertia>
            <ixx>1e-05</ixx>
            <ixy>0</ixy>
            <ixz>0</ixz>
            <iyy>2e-05</iyy>
            <iyz>0</iyz>
            <izz>2e-05</izz>
          </inertia>
        </inertial>
        <sensor name='imu_sensor' type='imu'>
          <pose>0 0 0 -3.14159 -0 0</pose>
          <always_on>1</always_on>
          <update_rate>1000</update_rate>
          <imu/>
        </sensor>
        <pose relative_to='iris::__model__'>0 0 0 0 -0 0</pose>
        <self_collide>0</self_collide>
        <enable_wind>0</enable_wind>
        <kinematic>0</kinematic>
      </link>
      <joint name='iris::iris/imu_joint' type='revolute'>
        <child>iris::iris/imu_link</child>
        <parent>iris::base_link</parent>
        <axis>
          <xyz expressed_in='iris::__model__'>0 0 1</xyz>
          <limit>
            <lower>0</lower>
            <upper>0</upper>
            <effort>0</effort>
            <velocity>0</velocity>
          </limit>
          <dynamics>
            <damping>1</damping>
            <spring_reference>0</spring_reference>
            <spring_stiffness>0</spring_stiffness>
          </dynamics>
        </axis>
        <physics>
          <ode>
            <implicit_spring_damper>1</implicit_spring_damper>
            <limit>
              <cfm>0</cfm>
              <erp>0.2</erp>
            </limit>
          </ode>
        </physics>
      </joint>
      <link name='iris::rotor_0'>
        <pose relative_to='iris::__model__'>0.13 -0.22 0.023 0 -0 0</pose>
        <inertial>
          <pose>0 0 0 0 -0 0</pose>
          <mass>0.025</mass>
          <inertia>
            <ixx>9.75e-06</ixx>
            <ixy>0</ixy>
            <ixz>0</ixz>
            <iyy>0.000166704</iyy>
            <iyz>0</iyz>
            <izz>0.000167604</izz>
          </inertia>
        </inertial>
        <collision name='rotor_0_collision'>
          <pose>0 0 0 0 -0 0</pose>
          <geometry>
            <cylinder>
              <length>0.005</length>
              <radius>0.1</radius>
            </cylinder>
          </geometry>
          <surface>
            <contact>
              <ode/>
            </contact>
            <friction>
              <ode/>
              <torsional>
                <ode/>
              </torsional>
            </friction>
            <bounce/>
          </surface>
          <max_contacts>10</max_contacts>
        </collision>
        <visual name='rotor_0_visual'>
          <pose>0 0 0 0 -0 0</pose>
          <geometry>
            <mesh>
              <scale>1 1 1</scale>
              <uri>model://iris_with_standoffs/meshes/iris_prop_ccw.dae</uri>
            </mesh>
          </geometry>
          <material>
            <script>
              <name>Gazebo/Blue</name>
              <uri>__default__</uri>
            </script>
          </material>
        </visual>
        <gravity>1</gravity>
        <velocity_decay/>
        <self_collide>0</self_collide>
        <enable_wind>0</enable_wind>
        <kinematic>0</kinematic>
      </link>
      <joint name='iris::rotor_0_joint' type='revolute'>
        <child>iris::rotor_0</child>
        <parent>iris::base_link</parent>
        <axis>
          <xyz expressed_in='iris::__model__'>0 0 1</xyz>
          <limit>
            <lower>-1e+16</lower>
            <upper>1e+16</upper>
          </limit>
          <dynamics>
            <damping>0.004</damping>
            <spring_reference>0</spring_reference>
            <spring_stiffness>0</spring_stiffness>
          </dynamics>
        </axis>
        <physics>
          <ode>
            <implicit_spring_damper>1</implicit_spring_damper>
            <limit>
              <cfm>0</cfm>
              <erp>0.2</erp>
            </limit>
          </ode>
        </physics>
      </joint>
      <link name='iris::rotor_1'>
        <pose relative_to='iris::__model__'>-0.13 0.2 0.023 0 -0 0</pose>
        <inertial>
          <pose>0 0 0 0 -0 0</pose>
          <mass>0.025</mass>
          <inertia>
            <ixx>9.75e-06</ixx>
            <ixy>0</ixy>
            <ixz>0</ixz>
            <iyy>0.000166704</iyy>
            <iyz>0</iyz>
            <izz>0.000167604</izz>
          </inertia>
        </inertial>
        <collision name='rotor_1_collision'>
          <pose>0 0 0 0 -0 0</pose>
          <geometry>
            <cylinder>
              <length>0.005</length>
              <radius>0.1</radius>
            </cylinder>
          </geometry>
          <surface>
            <contact>
              <ode/>
            </contact>
            <friction>
              <ode/>
              <torsional>
                <ode/>
              </torsional>
            </friction>
            <bounce/>
          </surface>
          <max_contacts>10</max_contacts>
        </collision>
        <visual name='rotor_1_visual'>
          <pose>0 0 0 0 -0 0</pose>
          <geometry>
            <mesh>
              <scale>1 1 1</scale>
              <uri>model://iris_with_standoffs/meshes/iris_prop_ccw.dae</uri>
            </mesh>
          </geometry>
          <material>
            <script>
              <name>Gazebo/DarkGrey</name>
              <uri>__default__</uri>
            </script>
          </material>
        </visual>
        <gravity>1</gravity>
        <velocity_decay/>
        <self_collide>0</self_collide>
        <enable_wind>0</enable_wind>
        <kinematic>0</kinematic>
      </link>
      <joint name='iris::rotor_1_joint' type='revolute'>
        <child>iris::rotor_1</child>
        <parent>iris::base_link</parent>
        <axis>
          <xyz expressed_in='iris::__model__'>0 0 1</xyz>
          <limit>
            <lower>-1e+16</lower>
            <upper>1e+16</upper>
          </limit>
          <dynamics>
            <damping>0.004</damping>
            <spring_reference>0</spring_reference>
            <spring_stiffness>0</spring_stiffness>
          </dynamics>
        </axis>
        <physics>
          <ode>
            <implicit_spring_damper>1</implicit_spring_damper>
            <limit>
              <cfm>0</cfm>
              <erp>0.2</erp>
            </limit>
          </ode>
        </physics>
      </joint>
      <link name='iris::rotor_2'>
        <pose relative_to='iris::__model__'>0.13 0.22 0.023 0 -0 0</pose>
        <inertial>
          <pose>0 0 0 0 -0 0</pose>
          <mass>0.025</mass>
          <inertia>
            <ixx>9.75e-06</ixx>
            <ixy>0</ixy>
            <ixz>0</ixz>
            <iyy>0.000166704</iyy>
            <iyz>0</iyz>
            <izz>0.000167604</izz>
          </inertia>
        </inertial>
        <collision name='rotor_2_collision'>
          <pose>0 0 0 0 -0 0</pose>
          <geometry>
            <cylinder>
              <length>0.005</length>
              <radius>0.1</radius>
            </cylinder>
          </geometry>
          <surface>
            <contact>
              <ode/>
            </contact>
            <friction>
              <ode/>
              <torsional>
                <ode/>
              </torsional>
            </friction>
            <bounce/>
          </surface>
          <max_contacts>10</max_contacts>
        </collision>
        <visual name='rotor_2_visual'>
          <pose>0 0 0 0 -0 0</pose>
          <geometry>
            <mesh>
              <scale>1 1 1</scale>
              <uri>model://iris_with_standoffs/meshes/iris_prop_cw.dae</uri>
            </mesh>
          </geometry>
          <material>
            <script>
              <name>Gazebo/Blue</name>
              <uri>__default__</uri>
            </script>
          </material>
        </visual>
        <gravity>1</gravity>
        <velocity_decay/>
        <self_collide>0</self_collide>
        <enable_wind>0</enable_wind>
        <kinematic>0</kinematic>
      </link>
      <joint name='iris::rotor_2_joint' type='revolute'>
        <child>iris::rotor_2</child>
        <parent>iris::base_link</parent>
        <axis>
          <xyz expressed_in='iris::__model__'>0 0 1</xyz>
          <limit>
            <lower>-1e+16</lower>
            <upper>1e+16</upper>
          </limit>
          <dynamics>
            <damping>0.004</damping>
            <spring_reference>0</spring_reference>
            <spring_stiffness>0</spring_stiffness>
          </dynamics>
        </axis>
        <physics>
          <ode>
            <implicit_spring_damper>1</implicit_spring_damper>
            <limit>
              <cfm>0</cfm>
              <erp>0.2</erp>
            </limit>
          </ode>
        </physics>
      </joint>
      <link name='iris::rotor_3'>
        <pose relative_to='iris::__model__'>-0.13 -0.2 0.023 0 -0 0</pose>
        <inertial>
          <pose>0 0 0 0 -0 0</pose>
          <mass>0.025</mass>
          <inertia>
            <ixx>9.75e-06</ixx>
            <ixy>0</ixy>
            <ixz>0</ixz>
            <iyy>0.000166704</iyy>
            <iyz>0</iyz>
            <izz>0.000167604</izz>
          </inertia>
        </inertial>
        <collision name='rotor_3_collision'>
          <pose>0 0 0 0 -0 0</pose>
          <geometry>
            <cylinder>
              <length>0.005</length>
              <radius>0.1</radius>
            </cylinder>
          </geometry>
          <surface>
            <contact>
              <ode/>
            </contact>
            <friction>
              <ode/>
              <torsional>
                <ode/>
              </torsional>
            </friction>
            <bounce/>
          </surface>
          <max_contacts>10</max_contacts>
        </collision>
        <visual name='rotor_3_visual'>
          <pose>0 0 0 0 -0 0</pose>
          <geometry>
            <mesh>
              <scale>1 1 1</scale>
              <uri>model://iris_with_standoffs/meshes/iris_prop_cw.dae</uri>
            </mesh>
          </geometry>
          <material>
            <script>
              <name>Gazebo/DarkGrey</name>
              <uri>__default__</uri>
            </script>
          </material>
        </visual>
        <gravity>1</gravity>
        <velocity_decay/>
        <self_collide>0</self_collide>
        <enable_wind>0</enable_wind>
        <kinematic>0</kinematic>
      </link>
      <joint name='iris::rotor_3_joint' type='revolute'>
        <child>iris::rotor_3</child>
        <parent>iris::base_link</parent>
        <axis>
          <xyz expressed_in='iris::__model__'>0 0 1</xyz>
          <limit>
            <lower>-1e+16</lower>
            <upper>1e+16</upper>
          </limit>
          <dynamics>
            <damping>0.004</damping>
            <spring_reference>0</spring_reference>
            <spring_stiffness>0</spring_stiffness>
          </dynamics>
        </axis>
        <physics>
          <ode>
            <implicit_spring_damper>1</implicit_spring_damper>
            <limit>
              <cfm>0</cfm>
              <erp>0.2</erp>
            </limit>
          </ode>
        </physics>
      </joint>
      <static>0</static>
      <frame name='gimbal_small_2d::__model__' attached_to='gimbal_small_2d::base_link'>
        <pose relative_to='__model__'>0 -0.01 0.07 1.57 -0 1.57</pose>
      </frame>
      <link name='gimbal_small_2d::base_link'>
        <inertial>
          <mass>0.2</mass>
          <inertia>
            <ixx>0.0001</ixx>
            <ixy>0</ixy>
            <ixz>0</ixz>
            <iyy>0.0001</iyy>
            <iyz>0</iyz>
            <izz>0.0001</izz>
          </inertia>
          <pose>0 0 0 0 -0 0</pose>
        </inertial>
        <visual name='base_main_viz'>
          <geometry>
            <mesh>
              <scale>0.001 0.001 0.001</scale>
              <uri>model://gimbal_small_2d/meshes/base_main.dae</uri>
            </mesh>
          </geometry>
          <material>
            <script>
              <uri>file://media/materials/scripts/gazebo.material</uri>
              <name>Gazebo/FlatBlack</name>
            </script>
          </material>
        </visual>
        <visual name='base_arm_viz'>
          <geometry>
            <mesh>
              <scale>0.001 0.001 0.001</scale>
              <uri>model://gimbal_small_2d/meshes/base_arm.dae</uri>
            </mesh>
          </geometry>
          <material>
            <script>
              <uri>file://media/materials/scripts/gazebo.material</uri>
              <name>Gazebo/FlatBlack</name>
            </script>
          </material>
        </visual>
        <collision name='base_col'>
          <pose>0.01 0.075 -0.025 0 -0 0</pose>
          <geometry>
            <box>
              <size>0.1 0.05 0.15</size>
            </box>
          </geometry>
          <surface>
            <friction>
              <ode>
                <mu>1</mu>
                <mu2>1</mu2>
                <fdir1>0 0 0</fdir1>
                <slip1>0</slip1>
                <slip2>0</slip2>
              </ode>
              <torsional>
                <ode/>
              </torsional>
            </friction>
            <contact>
              <ode/>
            </contact>
            <bounce/>
          </surface>
          <max_contacts>10</max_contacts>
        </collision>
        <pose relative_to='gimbal_small_2d::__model__'>0 0 0 0 -0 0</pose>
        <self_collide>0</self_collide>
        <enable_wind>0</enable_wind>
        <kinematic>0</kinematic>
      </link>
      <link name='gimbal_small_2d::tilt_link'>
        <inertial>
          <mass>0.07</mass>
          <inertia>
            <ixx>1e-05</ixx>
            <ixy>0</ixy>
            <ixz>0</ixz>
            <iyy>1e-05</iyy>
            <iyz>0</iyz>
            <izz>1e-05</izz>
          </inertia>
          <pose>0 0 0 0 -0 0</pose>
        </inertial>
        <visual name='tilt_viz'>
          <pose>0 0 -0.005 0 -0 0</pose>
          <geometry>
            <mesh>
              <scale>0.001 0.001 0.001</scale>
              <uri>model://gimbal_small_2d/meshes/tilt.dae</uri>
            </mesh>
          </geometry>
          <material>
            <script>
              <uri>file://media/materials/scripts/gazebo.material</uri>
              <name>Gazebo/Grey</name>
            </script>
          </material>
        </visual>
        <collision name='tilt_col'>
          <pose>0 0 -0.005 0 -0 0</pose>
          <geometry>
            <mesh>
              <scale>0.001 0.001 0.001</scale>
              <uri>model://gimbal_small_2d/meshes/tilt.dae</uri>
            </mesh>
          </geometry>
          <max_contacts>10</max_contacts>
          <surface>
            <contact>
              <ode/>
            </contact>
            <bounce/>
            <friction>
              <torsional>
                <ode/>
              </torsional>
              <ode/>
            </friction>
          </surface>
        </collision>
        <visual name='camera_viz'>
          <pose>0 0 0.02 0 -0 0</pose>
          <geometry>
            <cylinder>
              <radius>0.025</radius>
              <length>0.05</length>
            </cylinder>
          </geometry>
          <material>
            <script>
              <uri>file://media/materials/scripts/gazebo.material</uri>
              <name>Gazebo/Grey</name>
            </script>
          </material>
        </visual>
        <collision name='camera_col'>
          <pose>0 0 0.02 0 -0 0</pose>
          <geometry>
            <cylinder>
              <radius>0.025</radius>
              <length>0.05</length>
            </cylinder>
          </geometry>
          <max_contacts>10</max_contacts>
          <surface>
            <contact>
              <ode/>
            </contact>
            <bounce/>
            <friction>
              <torsional>
                <ode/>
              </torsional>
              <ode/>
            </friction>
          </surface>
        </collision>
        <sensor name='camera' type='camera'>
          <pose>0 0 0 -1.57 -1.57 -1.57</pose>
          <camera>
            <horizontal_fov>1.891325149</horizontal_fov>
            <image>
              <width>640</width>
              <height>480</height>
              <format>R8G8B8</format>
            </image>
            <clip>
              <near>0.1</near>
              <far>100</far>
            </clip>
          </camera>
          <plugin name='down_camera_controller' filename='libgazebo_ros_camera.so'>
            <robotNamespace>logitech</robotNamespace>
            <cameraName>fisheye</cameraName>
            <imageTopicName>fisheye_image_raw</imageTopicName>
            <cameraInfoTopicName>camera_info</cameraInfoTopicName>
            <frameName>logitech_link</frameName>
            <hackBaseline>0</hackBaseline>
          </plugin>
          <always_on>1</always_on>
          <update_rate>30</update_rate>
          <visualize>1</visualize>
        </sensor>
        <pose relative_to='gimbal_small_2d::__model__'>0 0 0 0 -0 0</pose>
        <self_collide>0</self_collide>
        <enable_wind>0</enable_wind>
        <kinematic>0</kinematic>
      </link>
      <joint name='gimbal_small_2d::tilt_joint' type='revolute'>
        <parent>gimbal_small_2d::base_link</parent>
        <child>gimbal_small_2d::tilt_link</child>
        <physics>
          <ode>
            <implicit_spring_damper>1</implicit_spring_damper>
            <limit>
              <cfm>0</cfm>
              <erp>0.2</erp>
            </limit>
          </ode>
        </physics>
        <axis>
          <xyz expressed_in='gimbal_small_2d::__model__'>1 0 0</xyz>
          <dynamics>
            <damping>0.5</damping>
            <spring_reference>0</spring_reference>
            <spring_stiffness>0</spring_stiffness>
          </dynamics>
          <limit>
            <lower>-0.1</lower>
            <upper>3.14159</upper>
            <effort>10</effort>
            <velocity>-1</velocity>
          </limit>
        </axis>
        <pose>0 0 0.02 0 -0 0</pose>
      </joint>
      <plugin name='gimbal_small_2d' filename='libGimbalSmall2dPlugin.so'>
        <joint>gimbal_small_2d::tilt_joint</joint>
      </plugin>
      <joint name='iris_gimbal_mount' type='revolute'>
        <parent>iris::base_link</parent>
        <child>gimbal_small_2d::base_link</child>
        <axis>
          <limit>
            <lower>0</lower>
            <upper>0</upper>
          </limit>
          <xyz expressed_in='__model__'>0 0 1</xyz>
          <dynamics>
            <spring_reference>0</spring_reference>
            <spring_stiffness>0</spring_stiffness>
          </dynamics>
        </axis>
      </joint>
      <frame name='realsense_biasa::__model__' attached_to='realsense_biasa::base_link'>
        <pose relative_to='__model__'>0 0.105 0.2 0 -0 1.5708</pose>
      </frame>
      <link name='realsense_biasa::base_link'>
        <inertial>
          <mass>0.0615752</mass>
          <inertia>
            <ixx>9.108e-05</ixx>
            <ixy>0</ixy>
            <ixz>0</ixz>
            <iyy>2.51e-06</iyy>
            <iyz>0</iyz>
            <izz>8.931e-05</izz>
          </inertia>
          <pose>0 0 0 0 -0 0</pose>
        </inertial>
        <self_collide>0</self_collide>
        <enable_wind>0</enable_wind>
        <kinematic>0</kinematic>
        <gravity>1</gravity>
        <visual name='visual'>
          <geometry>
            <mesh>
              <uri>model://realsense_biasa/meshes/realsense.dae</uri>
            </mesh>
          </geometry>
        </visual>
        <collision name='collision'>
          <laser_retro>0</laser_retro>
          <max_contacts>10</max_contacts>
          <pose>0 0 0 0 -0 0</pose>
          <geometry>
            <box>
              <size>0.0078 0.13 0.0192</size>
            </box>
          </geometry>
          <surface>
            <friction>
              <ode>
                <mu>1</mu>
                <mu2>1</mu2>
                <fdir1>0 0 0</fdir1>
                <slip1>0</slip1>
                <slip2>0</slip2>
              </ode>
              <torsional>
                <coefficient>1</coefficient>
                <patch_radius>0</patch_radius>
                <surface_radius>0</surface_radius>
                <use_patch_radius>1</use_patch_radius>
                <ode>
                  <slip>0</slip>
                </ode>
              </torsional>
            </friction>
            <bounce>
              <restitution_coefficient>0</restitution_coefficient>
              <threshold>1e+06</threshold>
            </bounce>
            <contact>
              <collide_without_contact>0</collide_without_contact>
              <collide_without_contact_bitmask>1</collide_without_contact_bitmask>
              <collide_bitmask>1</collide_bitmask>
              <ode>
                <soft_cfm>0</soft_cfm>
                <soft_erp>0.2</soft_erp>
                <kp>1e+13</kp>
                <kd>1</kd>
                <max_vel>0.01</max_vel>
                <min_depth>0</min_depth>
              </ode>
              <bullet>
                <split_impulse>1</split_impulse>
                <split_impulse_penetration_threshold>-0.01</split_impulse_penetration_threshold>
                <soft_cfm>0</soft_cfm>
                <soft_erp>0.2</soft_erp>
                <kp>1e+13</kp>
                <kd>1</kd>
              </bullet>
            </contact>
          </surface>
        </collision>
        <sensor name='camera' type='camera'>
          <camera>
            <horizontal_fov>0.8654</horizontal_fov>
            <image>
              <width>640</width>
              <height>480</height>
              <format>R8G8B8</format>
            </image>
            <clip>
              <near>0.1</near>
              <far>100</far>
            </clip>
          </camera>
          <plugin name='front_camera_controller' filename='libgazebo_ros_camera.so'>
            <robotNamespace>logitech</robotNamespace>
            <cameraName>webcam</cameraName>
            <imageTopicName>webcam_image_raw</imageTopicName>
            <cameraInfoTopicName>camera_info</cameraInfoTopicName>
            <frameName>rs_link</frameName>
            <hackBaseline>0</hackBaseline>
          </plugin>
        </sensor>
        <pose relative_to='realsense_biasa::__model__'>0 0 0 0 -0 0</pose>
      </link>
      <joint name='realsense_biasa_joint' type='revolute'>
        <child>realsense_biasa::base_link</child>
        <parent>iris::base_link</parent>
        <axis>
          <xyz>0 0 1</xyz>
          <limit>
            <upper>0</upper>
            <lower>0</lower>
          </limit>
          <dynamics>
            <spring_reference>0</spring_reference>
            <spring_stiffness>0</spring_stiffness>
          </dynamics>
        </axis>
      </joint>
      <plugin name='rotor_0_blade_1' filename='libLiftDragPlugin.so'>
        <a0>0.1</a0>
        <alpha_stall>1.4</alpha_stall>
        <cla>0.2500</cla>
        <cda>0.10</cda>
        <cma>0.00</cma>
        <cla_stall>-0.025</cla_stall>
        <cda_stall>0.0</cda_stall>
        <cma_stall>0.0</cma_stall>
        <area>0.2</area>
        <air_density>1.2041</air_density>
        <cp>0.084 0 0</cp>
        <forward>0 1 0</forward>
        <upward>0 0 1</upward>
        <link_name>iris::rotor_0</link_name>
      </plugin>
      <plugin name='rotor_0_blade_2' filename='libLiftDragPlugin.so'>
        <a0>0.1</a0>
        <alpha_stall>1.4</alpha_stall>
        <cla>0.2500</cla>
        <cda>0.10</cda>
        <cma>0.00</cma>
        <cla_stall>-0.025</cla_stall>
        <cda_stall>0.0</cda_stall>
        <cma_stall>0.0</cma_stall>
        <area>0.2</area>
        <air_density>1.2041</air_density>
        <cp>-0.084 0 0</cp>
        <forward>0 -1 0</forward>
        <upward>0 0 1</upward>
        <link_name>iris::rotor_0</link_name>
      </plugin>
      <plugin name='rotor_1_blade_1' filename='libLiftDragPlugin.so'>
        <a0>0.1</a0>
        <alpha_stall>1.4</alpha_stall>
        <cla>0.2500</cla>
        <cda>0.10</cda>
        <cma>0.00</cma>
        <cla_stall>-0.025</cla_stall>
        <cda_stall>0.0</cda_stall>
        <cma_stall>0.0</cma_stall>
        <area>0.2</area>
        <air_density>1.2041</air_density>
        <cp>0.084 0 0</cp>
        <forward>0 1 0</forward>
        <upward>0 0 1</upward>
        <link_name>iris::rotor_1</link_name>
      </plugin>
      <plugin name='rotor_1_blade_2' filename='libLiftDragPlugin.so'>
        <a0>0.1</a0>
        <alpha_stall>1.4</alpha_stall>
        <cla>0.2500</cla>
        <cda>0.10</cda>
        <cma>0.00</cma>
        <cla_stall>-0.025</cla_stall>
        <cda_stall>0.0</cda_stall>
        <cma_stall>0.0</cma_stall>
        <area>0.2</area>
        <air_density>1.2041</air_density>
        <cp>-0.084 0 0</cp>
        <forward>0 -1 0</forward>
        <upward>0 0 1</upward>
        <link_name>iris::rotor_1</link_name>
      </plugin>
      <plugin name='rotor_2_blade_1' filename='libLiftDragPlugin.so'>
        <a0>0.1</a0>
        <alpha_stall>1.4</alpha_stall>
        <cla>0.2500</cla>
        <cda>0.10</cda>
        <cma>0.00</cma>
        <cla_stall>-0.025</cla_stall>
        <cda_stall>0.0</cda_stall>
        <cma_stall>0.0</cma_stall>
        <area>0.2</area>
        <air_density>1.2041</air_density>
        <cp>0.084 0 0</cp>
        <forward>0 -1 0</forward>
        <upward>0 0 1</upward>
        <link_name>iris::rotor_2</link_name>
      </plugin>
      <plugin name='rotor_2_blade_2' filename='libLiftDragPlugin.so'>
        <a0>0.1</a0>
        <alpha_stall>1.4</alpha_stall>
        <cla>0.2500</cla>
        <cda>0.10</cda>
        <cma>0.00</cma>
        <cla_stall>-0.025</cla_stall>
        <cda_stall>0.0</cda_stall>
        <cma_stall>0.0</cma_stall>
        <area>0.2</area>
        <air_density>1.2041</air_density>
        <cp>-0.084 0 0</cp>
        <forward>0 1 0</forward>
        <upward>0 0 1</upward>
        <link_name>iris::rotor_2</link_name>
      </plugin>
      <plugin name='rotor_3_blade_1' filename='libLiftDragPlugin.so'>
        <a0>0.1</a0>
        <alpha_stall>1.4</alpha_stall>
        <cla>0.2500</cla>
        <cda>0.10</cda>
        <cma>0.00</cma>
        <cla_stall>-0.025</cla_stall>
        <cda_stall>0.0</cda_stall>
        <cma_stall>0.0</cma_stall>
        <area>0.2</area>
        <air_density>1.2041</air_density>
        <cp>0.084 0 0</cp>
        <forward>0 -1 0</forward>
        <upward>0 0 1</upward>
        <link_name>iris::rotor_3</link_name>
      </plugin>
      <plugin name='rotor_3_blade_2' filename='libLiftDragPlugin.so'>
        <a0>0.1</a0>
        <alpha_stall>1.4</alpha_stall>
        <cla>0.2500</cla>
        <cda>0.10</cda>
        <cma>0.00</cma>
        <cla_stall>-0.025</cla_stall>
        <cda_stall>0.0</cda_stall>
        <cma_stall>0.0</cma_stall>
        <area>0.2</area>
        <air_density>1.2041</air_density>
        <cp>-0.084 0 0</cp>
        <forward>0 1 0</forward>
        <upward>0 0 1</upward>
        <link_name>iris::rotor_3</link_name>
      </plugin>
      <plugin name='arducopter_plugin' filename='libArduCopterPlugin.so'>
        <imuName>iris_demo::iris::iris/imu_link::imu_sensor</imuName>
        <connectionTimeoutMaxCount>5</connectionTimeoutMaxCount>
        <rotor id='0'>
          <vel_p_gain>0.01</vel_p_gain>
          <vel_i_gain>0</vel_i_gain>
          <vel_d_gain>0</vel_d_gain>
          <vel_i_max>0</vel_i_max>
          <vel_i_min>0</vel_i_min>
          <vel_cmd_max>2.0</vel_cmd_max>
          <vel_cmd_min>-2.0</vel_cmd_min>
          <jointName>iris::rotor_0_joint</jointName>
          <turningDirection>ccw</turningDirection>
          <rotorVelocitySlowdownSim>1</rotorVelocitySlowdownSim>
        </rotor>
        <rotor id='1'>
          <vel_p_gain>0.01</vel_p_gain>
          <vel_i_gain>0</vel_i_gain>
          <vel_d_gain>0</vel_d_gain>
          <vel_i_max>0</vel_i_max>
          <vel_i_min>0</vel_i_min>
          <vel_cmd_max>2.0</vel_cmd_max>
          <vel_cmd_min>-2.0</vel_cmd_min>
          <jointName>iris::rotor_1_joint</jointName>
          <turningDirection>ccw</turningDirection>
          <rotorVelocitySlowdownSim>1</rotorVelocitySlowdownSim>
        </rotor>
        <rotor id='2'>
          <vel_p_gain>0.01</vel_p_gain>
          <vel_i_gain>0</vel_i_gain>
          <vel_d_gain>0</vel_d_gain>
          <vel_i_max>0</vel_i_max>
          <vel_i_min>0</vel_i_min>
          <vel_cmd_max>2.0</vel_cmd_max>
          <vel_cmd_min>-2.0</vel_cmd_min>
          <jointName>iris::rotor_2_joint</jointName>
          <turningDirection>cw</turningDirection>
          <rotorVelocitySlowdownSim>1</rotorVelocitySlowdownSim>
        </rotor>
        <rotor id='3'>
          <vel_p_gain>0.01</vel_p_gain>
          <vel_i_gain>0</vel_i_gain>
          <vel_d_gain>0</vel_d_gain>
          <vel_i_max>0</vel_i_max>
          <vel_i_min>0</vel_i_min>
          <vel_cmd_max>2.0</vel_cmd_max>
          <vel_cmd_min>-2.0</vel_cmd_min>
          <jointName>iris::rotor_3_joint</jointName>
          <turningDirection>cw</turningDirection>
          <rotorVelocitySlowdownSim>1</rotorVelocitySlowdownSim>
        </rotor>
      </plugin>
      <pose>0.014755 -0.073494 0 0 -0 0</pose>
    </model>

  </world>
</sdf>
